Workbook
Name FXRate: 'Budget Tracker'!$B$5
Name TripBudget: 'Budget Tracker'!$D$5

Sheet Dashboard
A1: 🇹🇼 TAIPEI, TAIWAN TRAVEL PLANNER
A2: ="Manila → Taipei | "&TEXT($C$9,"mmm d, yyyy")&" – "&TEXT($C$10,"mmm d, yyyy")&" ("&($C$10-$C$9)&"N/"&($C$10-$C$9+1)&"D)" -> Manila → Taipei | Mar 15, 2027 – Mar 20, 2027 (5N/6D)
A3: Blue text = editable input cell. Update Trip Summary here – dates, travelers and budget flow through the whole workbook automatically.
A6: TRIP SUMMARY | E6: BUDGET SUMMARY
A7: Destination | C7: Taipei, Taiwan | E7: Total Trip Budget (PHP) | G7: =TripBudget -> 50000
A8: Departure Airport | C8: Ninoy Aquino Intl Airport (MNL) | E8: Estimated Total Cost (PHP) | G8: ='Budget Tracker'!D26 -> 74932.62
A9: Departure Date | C9: 46461 | E9: Actual Spending (PHP) | G9: ='Budget Tracker'!D27 -> 22319.42
A10: Return Date | C10: 46466 | E10: Amount Already Paid (PHP) | G10: ='Budget Tracker'!D28 -> 22319.42
A11: Nights / Days | C11: =($C$10-$C$9)&" nights / "&($C$10-$C$9+1)&" days" -> 5 nights / 6 days | E11: Remaining Budget (PHP) | G11: ='Budget Tracker'!D29 -> 27680.58
A12: Number of Travelers | C12: 2 | E12: Cost per Traveler (PHP) | G12: ='Budget Tracker'!D32 -> 37466.31
A13: Hotel / Area | C13: Hotel near Zhongshan MRT, Zhongshan District
A14: Travel Style | C14: Mid-range
A15: TWD → PHP Rate | C15: ="1 TWD = "&TEXT(FXRate,"0.0000")&" PHP" -> 1 TWD = 1.9300 PHP
A16: PREPARATION PROGRESS
A17: Travel Documents | C17: =COUNTIF('Travel Documents'!$C$5:$C$18,"Done")/COUNTA('Travel Documents'!$A$5:$A$18) -> 0.071428571
A18: Bookings | C18: =COUNTIF(Bookings!$M$5:$M$14,"Confirmed")/COUNTA(Bookings!$A$5:$A$14) -> 0.2
A19: Payments | C19: =COUNTIF('Budget Tracker'!$H$8:$H$21,"Yes")/COUNTA('Budget Tracker'!$B$8:$B$21) -> 0.071428571
A20: Packing | C20: ='Packing & Pre-Trip'!D40 -> 0
A21: Pre-Trip Tasks | C21: ='Packing & Pre-Trip'!D72 -> 0
A22: Overall Readiness | C22: =AVERAGE(C17:C21) -> 0.068571429
A24: IMPORTANT BOOKINGS
A25: Booking | B25: Provider/Detail | C25: Date | D25: Cost (PHP) | E25: Status | F25: Notes
A26: Flight (Round-trip) | B26: =INDEX(Bookings!$B:$B,MATCH("Flight - Outbound",Bookings!$A:$A,0)) -> Cebu Pacific (5J) | C26: =INDEX(Bookings!$C:$C,MATCH("Flight - Outbound",Bookings!$A:$A,0)) -> 46461 | D26: =SUMPRODUCT(ISNUMBER(SEARCH("Flight",Bookings!$A$5:$A$14))*Bookings!$I$5:$I$14) -> 16500 | E26: =INDEX(Bookings!$M:$M,MATCH("Flight - Outbound",Bookings!$A:$A,0)) -> Confirmed | F26: =INDEX(Bookings!$O:$O,MATCH("Flight - Outbound",Bookings!$A:$A,0)) -> Departs Manila 11:35 PM Mar 15, arrives Taipei 2:00 AM Mar 16 (+1 day) · Confirm flight number, terminal and baggage allowance on the e-ticket · Promo fares are usually non-refundable
A27: Hotel | B27: =INDEX(Bookings!$B:$B,MATCH("Hotel",Bookings!$A:$A,0)) -> Agoda / Booking.com (sample) | C27: =INDEX(Bookings!$C:$C,MATCH("Hotel",Bookings!$A:$A,0)) -> 46462 | D27: =INDEX(Bookings!$I:$I,MATCH("Hotel",Bookings!$A:$A,0)) -> 6948 | E27: =INDEX(Bookings!$M:$M,MATCH("Hotel",Bookings!$A:$A,0)) -> Not Started | F27: =INDEX(Bookings!$O:$O,MATCH("Hotel",Bookings!$A:$A,0)) -> 4 nights (Mar 16–20) · Twin/Double room · Breakfast included · No 2nd hotel night needed – the 3:15 AM Mar 20 flight departs from the same night's stay
A28: Major Tour/Activity | B28: =INDEX(Bookings!$B:$B,MATCH("Tour - Jiufen & Shifen Day Trip",Bookings!$A:$A,0)) -> Klook / KKday (sample) | C28: =INDEX(Bookings!$C:$C,MATCH("Tour - Jiufen & Shifen Day Trip",Bookings!$A:$A,0)) -> 46465 | D28: =INDEX(Bookings!$I:$I,MATCH("Tour - Jiufen & Shifen Day Trip",Bookings!$A:$A,0)) -> 4632 | E28: =INDEX(Bookings!$M:$M,MATCH("Tour - Jiufen & Shifen Day Trip",Bookings!$A:$A,0)) -> Not Started | F28: =INDEX(Bookings!$O:$O,MATCH("Tour - Jiufen & Shifen Day Trip",Bookings!$A:$A,0)) -> 2 pax · Small-group day tour · Includes sky lantern · Runs on the last day – luggage stays at the hotel front desk after check-out
A29: Airport Transfer | B29: =INDEX(Bookings!$B:$B,MATCH("Airport Transfer - Arrival",Bookings!$A:$A,0)) -> Taoyuan Airport MRT / taxi | C29: =INDEX(Bookings!$C:$C,MATCH("Airport Transfer - Arrival",Bookings!$A:$A,0)) -> 46462 | D29: =INDEX(Bookings!$I:$I,MATCH("Airport Transfer - Arrival",Bookings!$A:$A,0)) -> 1930 | E29: =INDEX(Bookings!$M:$M,MATCH("Airport Transfer - Arrival",Bookings!$A:$A,0)) -> Not Started | F29: =INDEX(Bookings!$O:$O,MATCH("Airport Transfer - Arrival",Bookings!$A:$A,0)) -> 2 pax · Landing at 2:00 AM – first Airport MRT train is ~6:00 AM, so budget for a taxi (~NT$1,000–1,200) if heading straight to the hotel

Sheet Master Itinerary
A1: MASTER ITINERARY – 6 DAYS / 5 NIGHTS IN TAIPEI
A2: Geographically grouped by day. Backup activities noted for weather-dependent stops. Edit Day/Date/costs as your plans firm up.
A4: Day | B4: Date | C4: Time | D4: Activity | E4: Attraction | F4: Area/District | G4: Address | H4: MRT Station | I4: Transportation | J4: Travel Time | K4: Est. Cost (TWD) | L4: Est. Cost (PHP) | M4: Meal | N4: Reservation? | O4: Status | P4: Notes | Q4: Map/Search Link
A5: 1 | B5: =Dashboard!$C$9+0 -> 46461 | C5: 18:30 | D5: Head to airport | E5: NAIA Terminal 3, Manila | F5: Manila | G5: NAIA Terminal 3, Pasay City | H5: N/A | I5: Grab/car/taxi | J5: – | K5: 0 | L5: =K5*FXRate -> 0 | M5: None | N5: Not Required | O5: Not Started | P5: Cebu Pacific international flights depart from NAIA Terminal 3; allow at least 3 hours before an 11:35 PM departure | Q5: =IF(E5="","","https://www.google.com/maps/search/"&SUBSTITUTE(E5," ","+")) -> https://www.google.com/maps/search/NAIA+Terminal+3,+Manila
A6: 1 | B6: =Dashboard!$C$9+0 -> 46461 | C6: 20:35 | D6: Check-in & immigration | E6: NAIA Terminal 3, Manila | F6: Manila | G6: NAIA Terminal 3, Pasay City | H6: N/A | I6: – | J6: – | K6: 0 | L6: =K6*FXRate -> 0 | M6: Dinner | N6: Not Required | O6: Not Started | P6: Online check-in in advance if possible; grab dinner airside – confirm baggage allowance with Cebu Pacific before packing | Q6: =IF(E6="","","https://www.google.com/maps/search/"&SUBSTITUTE(E6," ","+")) -> https://www.google.com/maps/search/NAIA+Terminal+3,+Manila
A7: 1 | B7: =Dashboard!$C$9+0 -> 46461 | C7: 23:35 | D7: Depart Manila | E7: Cebu Pacific MNL → TPE | F7: Airport | G7: NAIA Terminal 3, Pasay City | H7: N/A | I7: Flight | J7: 2h25m | K7: 0 | L7: =K7*FXRate -> 0 | M7: None | N7: Confirmed | O7: Not Started | P7: Cebu Pacific, Manila (MNL) 11:35 PM → Taipei Taoyuan (TPE) 2:00 AM +1 day. Booking ref: Kimberly Domingo JPU86R · Kriza Blanca Domingo SKKC5G | Q7: =IF(E7="","","https://www.google.com/maps/search/"&SUBSTITUTE(E7," ","+")) -> https://www.google.com/maps/search/Cebu+Pacific+MNL+→+TPE
A8: 2 | B8: =Dashboard!$C$9+1 -> 46462 | C8: 02:00 | D8: Arrival & immigration | E8: Taoyuan International Airport (TPE) | F8: Airport | G8: Taoyuan Intl Airport, Taoyuan | H8: Airport (not MRT) | I8: Flight arrival | J8: – | K8: 0 | L8: =K8*FXRate -> 0 | M8: None | N8: Not Required | O8: Not Started | P8: Complete the Taiwan Arrival Card (TWAC) online within 3 days before landing – mandatory since Oct 2025, no paper form accepted | Q8: =IF(E8="","","https://www.google.com/maps/search/"&SUBSTITUTE(E8," ","+")) -> https://www.google.com/maps/search/Taoyuan+International+Airport+(TPE)
A9: 2 | B9: =Dashboard!$C$9+1 -> 46462 | C9: 03:30 | D9: Airport transfer to hotel | E9: Taoyuan Airport MRT → Taipei Main Station → Zhongshan | F9: Airport → Zhongshan | H9: Zhongshan Station | I9: Airport MRT + Red Line | J9: 45–60 min | K9: 160 | L9: =K9*FXRate -> 308.8 | M9: None | N9: Not Required | O9: Not Started | P9: First airport MRT departs ~6 AM – take a taxi/NT$1,000-1,200 if arriving this early, or rest airside until first train | Q9: =IF(E9="","","https://www.google.com/maps/search/"&SUBSTITUTE(E9," ","+")) -> https://www.google.com/maps/search/Taoyuan+Airport+MRT+→+Taipei+Main+Station+→+Zhongshan
A10: 2 | B10: =Dashboard!$C$9+1 -> 46462 | C10: 07:00 | D10: Rest / early check-in request | E10: Hotel near Zhongshan MRT | F10: Zhongshan | G10: Zhongshan District, Taipei | H10: Zhongshan Station | I10: Walk | J10: 10 min | K10: 0 | L10: =K10*FXRate -> 0 | M10: Breakfast | N10: Not Required | O10: Not Started | P10: Store luggage at front desk if the room isn't ready; standard check-in is usually 15:00 – nap at a 24-hr cafe or hotel lobby if needed | Q10: =IF(E10="","","https://www.google.com/maps/search/"&SUBSTITUTE(E10," ","+")) -> https://www.google.com/maps/search/Hotel+near+Zhongshan+MRT
A11: 2 | B11: =Dashboard!$C$9+1 -> 46462 | C11: 11:00 | D11: Temple visit | E11: Longshan Temple | F11: Wanhua | G11: No. 211 Guangzhou St, Wanhua District | H11: Longshan Temple Station | I11: MRT (Red Line) | J11: 20 min | K11: 0 | L11: =K11*FXRate -> 0 | M11: None | N11: Not Required | O11: Not Started | P11: Free entry (donations optional); open 6:00–22:00; dress modestly | Q11: =IF(E11="","","https://www.google.com/maps/search/"&SUBSTITUTE(E11," ","+")) -> https://www.google.com/maps/search/Longshan+Temple
A12: 2 | B12: =Dashboard!$C$9+1 -> 46462 | C12: 12:30 | D12: Lunch | E12: Local eatery near Wanhua | F12: Wanhua | G12: Wanhua District | H12: Longshan Temple Station | I12: Walk | J12: 5 min | K12: 250 | L12: =K12*FXRate -> 482.5 | M12: Lunch | N12: Not Required | O12: Not Started | P12: Beef noodle soup is a good pick here | Q12: =IF(E12="","","https://www.google.com/maps/search/"&SUBSTITUTE(E12," ","+")) -> https://www.google.com/maps/search/Local+eatery+near+Wanhua
A13: 2 | B13: =Dashboard!$C$9+1 -> 46462 | C13: 14:00 | D13: Memorial hall visit | E13: Chiang Kai-shek Memorial Hall | F13: Zhongzheng | G13: No. 21 Zhongshan S. Rd, Zhongzheng District | H13: CKS Memorial Hall Station | I13: MRT (Red Line) | J13: 15 min | K13: 0 | L13: =K13*FXRate -> 0 | M13: None | N13: Not Required | O13: Not Started | P13: Free entry; open 9:00–18:00; hourly changing-of-the-guard ceremony | Q13: =IF(E13="","","https://www.google.com/maps/search/"&SUBSTITUTE(E13," ","+")) -> https://www.google.com/maps/search/Chiang+Kai-shek+Memorial+Hall
A14: 2 | B14: =Dashboard!$C$9+1 -> 46462 | C14: 15:30 | D14: Hotel check-in | E14: Hotel near Zhongshan MRT | F14: Zhongshan | G14: Zhongshan District, Taipei | H14: Zhongshan Station | I14: MRT (Red Line) | J14: 15 min | K14: 0 | L14: =K14*FXRate -> 0 | M14: None | N14: Required | O14: Not Started | P14: Proper check-in and a chance to freshen up after the overnight flight | Q14: =IF(E14="","","https://www.google.com/maps/search/"&SUBSTITUTE(E14," ","+")) -> https://www.google.com/maps/search/Hotel+near+Zhongshan+MRT
A15: 2 | B15: =Dashboard!$C$9+1 -> 46462 | C15: 18:00 | D15: Dinner & evening stroll | E15: Ximending Pedestrian Area | F15: Wanhua | G15: Ximending, Wanhua District | H15: Ximen Station | I15: MRT (Red → Blue Line) | J15: 20 min | K15: 300 | L15: =K15*FXRate -> 579 | M15: Dinner | N15: Not Required | O15: Not Started | P15: Try scallion pancake and bubble tea; keep it low-key – an early night helps after the redeye. Rainy backup: Wonderful/Ximen indoor shopping arcades | Q15: =IF(E15="","","https://www.google.com/maps/search/"&SUBSTITUTE(E15," ","+")) -> https://www.google.com/maps/search/Ximending+Pedestrian+Area
A16: 3 | B16: =Dashboard!$C$9+2 -> 46463 | C16: 08:00 | D16: Breakfast | E16: Hotel area breakfast | F16: Zhongshan | G16: Zhongshan District | H16: Zhongshan Station | I16: Walk | J16: 10 min | K16: 150 | L16: =K16*FXRate -> 289.5 | M16: Breakfast | N16: Not Required | O16: Not Started | P16: Light breakfast – big day ahead | Q16: =IF(E16="","","https://www.google.com/maps/search/"&SUBSTITUTE(E16," ","+")) -> https://www.google.com/maps/search/Hotel+area+breakfast
A17: 3 | B17: =Dashboard!$C$9+2 -> 46463 | C17: 09:30 | D17: Observation deck | E17: Taipei 101 Observatory | F17: Xinyi | G17: No. 7, Sec 5, Xinyi Rd, Xinyi District | H17: Taipei 101/World Trade Center Station | I17: MRT (Red Line) | J17: 20 min | K17: 600 | L17: =K17*FXRate -> 1158 | M17: None | N17: Recommended | O17: Not Started | P17: Book online in advance for a small discount and shorter queue; open 10:00–21:00 | Q17: =IF(E17="","","https://www.google.com/maps/search/"&SUBSTITUTE(E17," ","+")) -> https://www.google.com/maps/search/Taipei+101+Observatory
A18: 3 | B18: =Dashboard!$C$9+2 -> 46463 | C18: 12:00 | D18: Lunch | E18: Taipei 101 Mall food options | F18: Xinyi | G18: Taipei 101 Mall, Xinyi District | H18: Taipei 101/World Trade Center Station | I18: Walk | J18: 5 min | K18: 350 | L18: =K18*FXRate -> 675.5 | M18: Lunch | N18: Not Required | O18: Not Started | P18: Wide range of dining options, from food court to sit-down | Q18: =IF(E18="","","https://www.google.com/maps/search/"&SUBSTITUTE(E18," ","+")) -> https://www.google.com/maps/search/Taipei+101+Mall+food+options
A19: 3 | B19: =Dashboard!$C$9+2 -> 46463 | C19: 14:00 | D19: Free time / shopping | E19: Xinyi Shopping District | F19: Xinyi | G19: Xinyi District | H19: Taipei 101/World Trade Center Station | I19: Walk | J19: – | K19: 500 | L19: =K19*FXRate -> 965 | M19: None | N19: Not Required | O19: Not Started | P19: Malls, flagship stores, department stores | Q19: =IF(E19="","","https://www.google.com/maps/search/"&SUBSTITUTE(E19," ","+")) -> https://www.google.com/maps/search/Xinyi+Shopping+District
A20: 3 | B20: =Dashboard!$C$9+2 -> 46463 | C20: 16:30 | D20: Sunset hike | E20: Elephant Mountain (Xiangshan) | F20: Xinyi | G20: Xiangshan Trailhead, Xinyi District | H20: Xiangshan Station | I20: MRT + walk | J20: 15 min | K20: 0 | L20: =K20*FXRate -> 0 | M20: None | N20: Not Required | O20: Not Started | P20: Free; bring water and wear proper shoes; weather-dependent – rainy backup: Taipei 101 indoor observatory or Songshan Cultural Park | Q20: =IF(E20="","","https://www.google.com/maps/search/"&SUBSTITUTE(E20," ","+")) -> https://www.google.com/maps/search/Elephant+Mountain+(Xiangshan)
A21: 3 | B21: =Dashboard!$C$9+2 -> 46463 | C21: 19:00 | D21: Dinner | E21: Raohe Street Night Market | F21: Songshan | G21: Raohe St, Songshan District | H21: Songshan Station | I21: MRT (Green Line) | J21: 10 min | K21: 300 | L21: =K21*FXRate -> 579 | M21: Dinner | N21: Not Required | O21: Not Started | P21: Famous for hu jiao bing (black pepper bun); enter from Ciyou Temple end | Q21: =IF(E21="","","https://www.google.com/maps/search/"&SUBSTITUTE(E21," ","+")) -> https://www.google.com/maps/search/Raohe+Street+Night+Market
A22: 4 | B22: =Dashboard!$C$9+3 -> 46464 | C22: 08:00 | D22: Breakfast | E22: Hotel area breakfast | F22: Zhongshan | G22: Zhongshan District | H22: Zhongshan Station | I22: Walk | J22: 10 min | K22: 150 | L22: =K22*FXRate -> 289.5 | M22: Breakfast | N22: Not Required | O22: Not Started | P22: Fuel up before a full day out | Q22: =IF(E22="","","https://www.google.com/maps/search/"&SUBSTITUTE(E22," ","+")) -> https://www.google.com/maps/search/Hotel+area+breakfast
A23: 4 | B23: =Dashboard!$C$9+3 -> 46464 | C23: 09:00 | D23: Museum visit | E23: National Palace Museum | F23: Shilin | G23: No. 221, Sec 2, Zhishan Rd, Shilin District | H23: Shilin Station + bus | I23: MRT + shuttle bus | J23: 30 min | K23: 350 | L23: =K23*FXRate -> 675.5 | M23: None | N23: Recommended | O23: Not Started | P23: Closed Mondays – confirm open days before booking; open Tue–Sun 9:00–17:00; pre-book tickets online | Q23: =IF(E23="","","https://www.google.com/maps/search/"&SUBSTITUTE(E23," ","+")) -> https://www.google.com/maps/search/National+Palace+Museum
A24: 4 | B24: =Dashboard!$C$9+3 -> 46464 | C24: 12:30 | D24: Lunch | E24: Eatery near National Palace Museum | F24: Shilin | G24: Shilin District | H24: Shilin Station | I24: Walk | J24: 5 min | K24: 400 | L24: =K24*FXRate -> 772 | M24: Lunch | N24: Not Required | O24: Not Started | P24: Silks Palace on-site, or casual options nearby | Q24: =IF(E24="","","https://www.google.com/maps/search/"&SUBSTITUTE(E24," ","+")) -> https://www.google.com/maps/search/Eatery+near+National+Palace+Museum
A25: 4 | B25: =Dashboard!$C$9+3 -> 46464 | C25: 14:00 | D25: Travel to Beitou | E25: Beitou District | F25: Beitou | H25: Beitou / Xinbeitou Station | I25: MRT (Red Line) | J25: 25 min | K25: 0 | L25: =K25*FXRate -> 0 | M25: None | N25: Not Required | O25: Not Started | P25: Transfer at Beitou Station to the pink Xinbeitou branch line | Q25: =IF(E25="","","https://www.google.com/maps/search/"&SUBSTITUTE(E25," ","+")) -> https://www.google.com/maps/search/Beitou+District
A26: 4 | B26: =Dashboard!$C$9+3 -> 46464 | C26: 14:30 | D26: Hot spring & thermal valley | E26: Beitou Hot Spring / Thermal Valley | F26: Beitou | G26: Zhongshan Rd, Beitou District | H26: Xinbeitou Station | I26: Walk | J26: 10 min | K26: 600 | L26: =K26*FXRate -> 1158 | M26: None | N26: Recommended | O26: Not Started | P26: Public or private spa options vary in price; weather-dependent for the outdoor Thermal Valley walk – rainy backup: Beitou Hot Spring Museum (indoor) | Q26: =IF(E26="","","https://www.google.com/maps/search/"&SUBSTITUTE(E26," ","+")) -> https://www.google.com/maps/search/Beitou+Hot+Spring+/+Thermal+Valley
A27: 4 | B27: =Dashboard!$C$9+3 -> 46464 | C27: 18:00 | D27: Dinner & night market | E27: Shilin Night Market | F27: Shilin | G27: Jihe Rd/Wenlin Rd, Shilin District | H27: Jiantan Station | I27: MRT (Red Line) | J27: 20 min | K27: 300 | L27: =K27*FXRate -> 579 | M27: Dinner | N27: Not Required | O27: Not Started | P27: One of Taipei's largest night markets – try oyster omelet and fried chicken | Q27: =IF(E27="","","https://www.google.com/maps/search/"&SUBSTITUTE(E27," ","+")) -> https://www.google.com/maps/search/Shilin+Night+Market
A28: 5 | B28: =Dashboard!$C$9+4 -> 46465 | C28: 07:00 | D28: Breakfast & pack up | E28: Hotel area breakfast; pack for the day | F28: Zhongshan | G28: Zhongshan District | H28: Zhongshan Station | I28: Walk | J28: 10 min | K28: 150 | L28: =K28*FXRate -> 289.5 | M28: Breakfast | N28: Not Required | O28: Not Started | P28: Pack a day bag – you'll head straight to the airport tonight after this day trip | Q28: =IF(E28="","","https://www.google.com/maps/search/"&SUBSTITUTE(E28," ","+")) -> https://www.google.com/maps/search/Hotel+area+breakfast;+pack+for+the+day
A29: 5 | B29: =Dashboard!$C$9+4 -> 46465 | C29: 07:30 | D29: Hotel check-out | E29: Hotel check-out, store luggage | F29: Zhongshan | G29: Zhongshan District | H29: Zhongshan Station | I29: – | J29: – | K29: 0 | L29: =K29*FXRate -> 0 | M29: None | N29: Not Required | O29: Not Started | P29: Ask the front desk to hold luggage for the day since there's no second hotel night | Q29: =IF(E29="","","https://www.google.com/maps/search/"&SUBSTITUTE(E29," ","+")) -> https://www.google.com/maps/search/Hotel+check-out,+store+luggage
A30: 5 | B30: =Dashboard!$C$9+4 -> 46465 | C30: 08:00 | D30: Day trip departure | E30: Depart for Jiufen & Shifen | F30: Zhongshan → New Taipei City | I30: Tour pickup / Pingxi rail line | J30: 1–1.5 hr | K30: 2400 | L30: =K30*FXRate -> 4632 | M30: None | N30: Required | O30: Not Started | P30: Book the day tour (or DIY via TRA + Pingxi Line) in advance; mountain weather can change quickly – backup: reschedule tea-house time indoors | Q30: =IF(E30="","","https://www.google.com/maps/search/"&SUBSTITUTE(E30," ","+")) -> https://www.google.com/maps/search/Depart+for+Jiufen+&+Shifen
A31: 5 | B31: =Dashboard!$C$9+4 -> 46465 | C31: 09:30 | D31: Sky lantern & waterfall | E31: Shifen Old Street & Shifen Waterfall | F31: Shifen, New Taipei City | G31: Shifen Old Street, Pingxi District | H31: Shifen Station (Pingxi Line) | I31: Tour van / train | J31: – | K31: 150 | L31: =K31*FXRate -> 289.5 | M31: None | N31: Not Required | O31: Not Started | P31: Sky lantern release on the old railway tracks; mind the trains | Q31: =IF(E31="","","https://www.google.com/maps/search/"&SUBSTITUTE(E31," ","+")) -> https://www.google.com/maps/search/Shifen+Old+Street+&+Shifen+Waterfall
A32: 5 | B32: =Dashboard!$C$9+4 -> 46465 | C32: 12:00 | D32: Lunch | E32: Shifen Old Street eatery | F32: Shifen | G32: Shifen Old Street | H32: Shifen Station | I32: Walk | J32: – | K32: 250 | L32: =K32*FXRate -> 482.5 | M32: Lunch | N32: Not Required | O32: Not Started | P32: Simple noodle and rice dishes along the tracks | Q32: =IF(E32="","","https://www.google.com/maps/search/"&SUBSTITUTE(E32," ","+")) -> https://www.google.com/maps/search/Shifen+Old+Street+eatery
A33: 5 | B33: =Dashboard!$C$9+4 -> 46465 | C33: 14:00 | D33: Old street & tea house | E33: Jiufen Old Street | F33: Jiufen, New Taipei City | G33: Jiufen Old Street, Ruifang District | H33: Tour van / bus 788/825 | I33: Tour van / bus | J33: 30–45 min | K33: 300 | L33: =K33*FXRate -> 579 | M33: None | N33: Not Required | O33: Not Started | P33: Narrow, crowded lanes – wear comfortable shoes; try a hillside tea house | Q33: =IF(E33="","","https://www.google.com/maps/search/"&SUBSTITUTE(E33," ","+")) -> https://www.google.com/maps/search/Jiufen+Old+Street
A34: 5 | B34: =Dashboard!$C$9+4 -> 46465 | C34: 17:00 | D34: Sunset viewpoint | E34: Jiufen Teahouse Lookout | F34: Jiufen | G34: Jiufen Old Street | I34: Walk | J34: – | K34: 0 | L34: =K34*FXRate -> 0 | M34: None | N34: Not Required | O34: Not Started | P34: Golden hour over the coastline; weather-dependent view – backup: stay in a tea house | Q34: =IF(E34="","","https://www.google.com/maps/search/"&SUBSTITUTE(E34," ","+")) -> https://www.google.com/maps/search/Jiufen+Teahouse+Lookout
A35: 5 | B35: =Dashboard!$C$9+4 -> 46465 | C35: 18:30 | D35: Dinner & return | E35: Dinner in Jiufen, then return to Taipei | F35: Jiufen → Zhongshan | I35: Tour van / bus | J35: 1–1.5 hr | K35: 300 | L35: =K35*FXRate -> 579 | M35: Dinner | N35: Not Required | O35: Not Started | P35: Arrive back in Taipei roughly 20:00–20:30; collect luggage from the hotel | Q35: =IF(E35="","","https://www.google.com/maps/search/"&SUBSTITUTE(E35," ","+")) -> https://www.google.com/maps/search/Dinner+in+Jiufen,+then+return+to+Taipei
A36: 5 | B36: =Dashboard!$C$9+4 -> 46465 | C36: 21:00 | D36: Collect luggage & head to airport | E36: Hotel (Zhongshan) → Taoyuan Airport | F36: Zhongshan → Airport | H36: Zhongshan Station | I36: Red Line + Airport MRT / taxi | J36: 60–90 min | K36: 320 | L36: =K36*FXRate -> 617.6 | M36: None | N36: Not Required | O36: Not Started | P36: Depart by ~21:00–21:30 to reach the airport with time to spare for the 3:15 AM flight; Airport MRT runs until around midnight, taxi after that | Q36: =IF(E36="","","https://www.google.com/maps/search/"&SUBSTITUTE(E36," ","+")) -> https://www.google.com/maps/search/Hotel+(Zhongshan)+→+Taoyuan+Airport
A37: 6 | B37: =Dashboard!$C$9+5 -> 46466 | C37: 00:30 | D37: Check-in & immigration | E37: Taoyuan International Airport (TPE) | F37: Airport | G37: Taoyuan Intl Airport, Taoyuan | H37: Airport (not MRT) | I37: – | J37: – | K37: 0 | L37: =K37*FXRate -> 0 | M37: None | N37: Not Required | O37: Not Started | P37: Very early departure – check-in counters typically open a few hours before; confirm exact opening time with Cebu Pacific | Q37: =IF(E37="","","https://www.google.com/maps/search/"&SUBSTITUTE(E37," ","+")) -> https://www.google.com/maps/search/Taoyuan+International+Airport+(TPE)
A38: 6 | B38: =Dashboard!$C$9+5 -> 46466 | C38: 03:15 | D38: Departure flight | E38: Cebu Pacific TPE → MNL | F38: Airport | G38: Taoyuan Intl Airport, Taoyuan | I38: Flight | J38: 2h30m | K38: 0 | L38: =K38*FXRate -> 0 | M38: None | N38: Confirmed | O38: Not Started | P38: Cebu Pacific, Taipei Taoyuan (TPE) 3:15 AM → Manila (MNL) 5:45 AM. Booking ref: Kimberly Domingo JPU86R · Kriza Blanca Domingo SKKC5G – trip complete, safe travels home! | Q38: =IF(E38="","","https://www.google.com/maps/search/"&SUBSTITUTE(E38," ","+")) -> https://www.google.com/maps/search/Cebu+Pacific+TPE+→+MNL

Sheet Travel Documents
A1: TRAVEL REQUIREMENTS & DOCUMENTS – Philippine Passport Holder → Taiwan
A2: Entry rules change — recheck every item against the Official Source column before departure. Last verified: Aug 20, 2026.
A4: Requirement | B4: Required? | C4: Status | D4: Deadline | E4: Cost | F4: Expiration Date | G4: Document/Ref # | H4: Digital Copy? | I4: Printed Copy? | J4: Official Source | K4: Last Verified | L4: Notes
A5: Philippine passport (original) | B5: Yes | C5: Done | D5: =Dashboard!$C$9-90 -> 46371 | E5: 0 | H5: No | I5: No | J5: Philippine DFA (dfa.gov.ph) | K5: 46254 | L5: Bring the physical passport; a photocopy is not accepted at check-in or immigration
A6: Passport validity check (6+ months beyond stay) | B6: Yes | C6: Not Started | D6: =Dashboard!$C$9-90 -> 46371 | E6: 0 | H6: No | I6: No | J6: TECO in the Philippines (roc-taiwan.org) | K6: 46254 | L6: Taiwan requires passport validity of at least 6 months from date of entry
A7: Visa / visa-free eligibility | B7: No visa needed | C7: Not Started | D7: =Dashboard!$C$9-60 -> 46401 | E7: 0 | H7: No | I7: No | J7: TECO in the Philippines (roc-taiwan.org) | K7: 46254 | L7: As of Aug 2026: Philippine passport holders enter visa-free for up to 14 days under the trial scheme – CONFIRM the current end date before booking, as it is periodically renewed
A8: Taiwan entry requirements (general) | B8: Yes | C8: Not Started | D8: =Dashboard!$C$9-30 -> 46431 | E8: 0 | H8: No | I8: No | J8: National Immigration Agency (nia.gov.tw) | K8: 46254 | L8: Covers passport validity, onward ticket, accommodation proof and sufficient funds
A9: Taiwan Arrival Card (TWAC) – online submission | B9: Yes | C9: Not Started | D9: =Dashboard!$C$9-1 -> 46460 | E9: 0 | H9: No | I9: No | J9: twac.immigration.gov.tw (official, free) | K9: 46254 | L9: Mandatory since Oct 1, 2025 – no paper form. Submit within 3 days before arrival (day of arrival counts); avoid third-party sites that charge a fee
A10: Return / onward flight ticket | B10: Yes | C10: Not Started | D10: =Dashboard!$C$9-45 -> 46416 | E10: – | H10: No | I10: No | J10: Airline booking confirmation | K10: 46254 | L10: May be checked at check-in and by immigration on arrival
A11: Hotel / accommodation confirmation | B11: Yes | C11: Not Started | D11: =Dashboard!$C$9-30 -> 46431 | E11: – | H11: No | I11: No | J11: Booking platform confirmation email | K11: 46254 | L11: Print or save a screenshot in case Wi-Fi is unavailable at immigration
A12: Travel insurance | B12: Recommended | C12: Not Started | D12: =Dashboard!$C$9-30 -> 46431 | E12: – | H12: No | I12: No | J12: Insurance provider | K12: 46254 | L12: Not mandatory for visa-free entry, but strongly recommended for medical emergencies and trip delays
A13: Proof of sufficient funds | B13: Conditional | C13: Not Started | D13: =Dashboard!$C$9-1 -> 46460 | E13: – | H13: No | I13: No | J13: Bank/cash on hand | K13: 46254 | L13: May be requested by immigration officers on a discretionary basis
A14: Flight confirmation / e-ticket (both legs) | B14: Yes | C14: Not Started | D14: =Dashboard!$C$9-1 -> 46460 | E14: – | H14: No | I14: No | J14: Airline booking confirmation | K14: 46254 | L14: Keep a saved PDF copy accessible offline
A15: General immigration document check | B15: Yes | C15: Not Started | D15: =Dashboard!$C$9-1 -> 46460 | E15: – | H15: No | I15: No | J15: National Immigration Agency (nia.gov.tw) | K15: 46254 | L15: Have passport, TWAC confirmation and onward ticket ready together at the counter
A16: Photocopies of passport (physical) | B16: Recommended | C16: Not Started | D16: =Dashboard!$C$9-14 -> 46447 | E16: – | H16: No | I16: No | J16: Self-prepared | K16: 46254 | L16: Keep separate from the original in case of loss or theft
A17: Digital document backups (cloud/email) | B17: Recommended | C17: Not Started | D17: =Dashboard!$C$9-14 -> 46447 | E17: – | H17: No | I17: No | J17: Self-prepared (cloud drive/email to self) | K17: 46254 | L17: Store passport, tickets, hotel and insurance PDFs in a cloud folder
A18: Emergency contact list | B18: Recommended | C18: Not Started | D18: =Dashboard!$C$9-7 -> 46454 | E18: – | H18: No | I18: No | J18: Self-prepared | K18: 46254 | L18: Include Philippine Representative Office in Taiwan (MECO) contact number and next-of-kin details
A20: EMERGENCY CONTACTS – Philippines ↔ Taiwan
A21: Save these to your phone before you fly – you may not have signal right when you need them. Numbers verified Aug 2026; reconfirm close to departure.
A22: Contact | B22: Phone / Number | C22: Notes
A23: Taiwan Police (general emergency) | B23: 110 | C23: For theft, robbery, accidents, or feeling unsafe
A24: Taiwan Fire / Ambulance (general emergency) | B24: 119 | C24: For fire or any medical emergency
A25: MECO Taipei – 24/7 Emergency Hotline | B25: 02-2658-8550 | C25: Philippine Representative Office in Taiwan – for Filipino nationals in life-threatening situations only
A26: MECO Taipei – General / Consular Line | B26: 02-2658-8825 | C26: Office hours Mon–Fri, 8:00 AM–4:00 PM – for passport, visa, and consular concerns (not emergencies)
A27: MECO Taipei – Address | B27: 2F, Chang Hong New Era Building, 55 & 57 Zhouzi St, Neihu District, Taipei 114 | C27: Nearest Philippine representative office to Taipei city center
A28: Cebu Pacific – Customer Service (Philippines) | B28: (02) 8702-0888 | C28: For flight changes, baggage issues, or delays – reconfirm this number closer to departure as airline hotlines change
A29: Hotel Front Desk | B29: Add once booked | C29: Fill in once your hotel is confirmed
A30: Travel Insurance – Emergency Assistance Line | B30: Add from policy | C30: Fill in from your insurance policy documents

Sheet Budget Tracker
A1: BUDGET & EXPENSE TRACKER
A2: Blue text = editable input cell. All PHP figures are calculated from the exchange rate cell below.
A4: EXCHANGE RATE (EDIT HERE) | D4: TOTAL TRIP BUDGET (PHP)
A5: 1 TWD = | B5: 1.93 | C5: PHP (mid-market ref. rate, Aug 2026 – update before travel / with your money changer's rate) | D5: 50000 | E5: for 2 travelers, 6D5N, mid-range style
A7: Date | B7: Category | C7: Description | D7: Estimated TWD | E7: Actual TWD | F7: Estimated PHP | G7: Actual PHP | H7: Paid? | I7: Payment Method | J7: Traveler | K7: Notes
A8: =Dashboard!$C$9-220 -> 46241 | B8: Flights | C8: Round-trip airfare, Cebu Pacific Manila↔Taipei (2 pax) | E8: 22319.42 | F8: 22319.42 | G8: =IF(E8="",0,E8) -> 22319.42 | H8: Yes | I8: UB Creditcard | J8: Kimberly & Kriza Domingo | K8: Booked – Kimberly: JPU86R · Kriza: SKKC5G. Priced in PHP – update with actual fare paid
A9: =Dashboard!$C$9+1 -> 46462 | B9: Hotel | C9: 4 nights, hotel near Zhongshan MRT (2 pax sharing) | D9: 3600 | F9: =D9*FXRate -> 6948 | G9: =IF(E9="",0,E9)*FXRate -> 0 | H9: No | J9: Kimberly & Kriza Domingo | K9: Paid on-site in TWD; breakfast included
A10: =Dashboard!$C$9-45 -> 46416 | B10: Travel insurance | C10: Single-trip travel insurance (2 pax) | F10: 900 | G10: =IF(E10="",0,E10) -> 0 | H10: No | J10: Kimberly & Kriza Domingo | K10: Priced in PHP – buy online before departure
A11: =Dashboard!$C$9 -> 46461 | B11: Airport transportation | C11: Airport MRT, arrival + departure transfers (2 pax) | D11: 640 | F11: =D11*FXRate -> 1235.2 | G11: =IF(E11="",0,E11)*FXRate -> 0 | H11: No | J11: Kimberly & Kriza Domingo | K11: Taoyuan Airport MRT Express both ways
A12: =Dashboard!$C$9+1 -> 46462 | B12: MRT/local transportation | C12: EasyCard top-ups for the trip (2 pax) | D12: 1000 | F12: =D12*FXRate -> 1930 | G12: =IF(E12="",0,E12)*FXRate -> 0 | H12: No | J12: Kimberly & Kriza Domingo | K12: MRT, bus and YouBike – top up as needed
A13: =Dashboard!$C$9+1 -> 46462 | B13: Food | C13: Daily food budget – breakfast/lunch/dinner (6 days, 2 pax) | D13: 9600 | F13: =D13*FXRate -> 18528 | G13: =IF(E13="",0,E13)*FXRate -> 0 | H13: No | J13: Kimberly & Kriza Domingo | K13: Mid-range estimate; night-market meals are cheaper, sit-down dinners more
A14: =Dashboard!$C$9+2 -> 46463 | B14: Attractions | C14: Taipei 101 Observatory tickets (2 pax) | D14: 1200 | F14: =D14*FXRate -> 2316 | G14: =IF(E14="",0,E14)*FXRate -> 0 | H14: No | J14: Kimberly & Kriza Domingo | K14: Standard 89F observatory ticket
A15: =Dashboard!$C$9+3 -> 46464 | B15: Attractions | C15: National Palace Museum tickets (2 pax) | D15: 700 | F15: =D15*FXRate -> 1351 | G15: =IF(E15="",0,E15)*FXRate -> 0 | H15: No | J15: Kimberly & Kriza Domingo | K15: Regular adult ticket
A16: =Dashboard!$C$9+4 -> 46465 | B16: Tours | C16: Jiufen & Shifen day tour (2 pax) | D16: 2400 | F16: =D16*FXRate -> 4632 | G16: =IF(E16="",0,E16)*FXRate -> 0 | H16: No | J16: Kimberly & Kriza Domingo | K16: Small-group tour with sky lantern experience
A17: =Dashboard!$C$9 -> 46461 | B17: SIM/eSIM | C17: 6-day unlimited data SIM/eSIM (2 pax) | D17: 600 | F17: =D17*FXRate -> 1158 | G17: =IF(E17="",0,E17)*FXRate -> 0 | H17: No | J17: Kimberly & Kriza Domingo | K17: Collect at airport or install before departure
A18: =Dashboard!$C$9+3 -> 46464 | B18: Shopping | C18: General shopping allowance | D18: 3000 | F18: =D18*FXRate -> 5790 | G18: =IF(E18="",0,E18)*FXRate -> 0 | H18: No | J18: Kimberly & Kriza Domingo | K18: Clothes, cosmetics, specialty goods
A19: =Dashboard!$C$9+3 -> 46464 | B19: Souvenirs | C19: Pineapple cakes, gifts, keepsakes | D19: 1500 | F19: =D19*FXRate -> 2895 | G19: =IF(E19="",0,E19)*FXRate -> 0 | H19: No | J19: Kimberly & Kriza Domingo | K19: Buy near airport for fresher pineapple cakes
A20: =Dashboard!$C$9 -> 46461 | B20: Emergency fund | C20: Cash buffer for unexpected costs | F20: 3000 | G20: =IF(E20="",0,E20) -> 0 | H20: No | J20: Kimberly & Kriza Domingo | K20: Kept aside, PHP equivalent carried as cash/card
A21: =Dashboard!$C$9+2 -> 46463 | B21: Miscellaneous | C21: Tips, incidentals, extra snacks | D21: 1000 | F21: =D21*FXRate -> 1930 | G21: =IF(E21="",0,E21)*FXRate -> 0 | H21: No | J21: Kimberly & Kriza Domingo | K21: Buffer for anything uncategorized
A23: BUDGET SUMMARY
A24: Total Estimated (TWD) | D24: =SUM(D8:D21) -> 25240
A25: Total Actual (TWD) | D25: =SUM(E8:E21) -> 22319.42
A26: Total Estimated (PHP) | D26: =SUM(F8:F21) -> 74932.62
A27: Total Actual (PHP) | D27: =SUM(G8:G21) -> 22319.42
A28: Total Paid (PHP) | D28: =SUMIF(H8:H21,"Yes",G8:G21) -> 22319.42
A29: Remaining Budget vs. Actual (PHP) | D29: =TripBudget-D27 -> 27680.58
A30: Remaining Budget vs. Estimate (PHP) | D30: =TripBudget-D26 -> -24932.62
A31: Difference: Actual vs Estimated (PHP) | D31: =D27-D26 -> -52613.2
A32: Cost per Traveler, Estimated (PHP) | D32: =IFERROR(D26/Dashboard!$C$12,0) -> 37466.31
A34: CATEGORY SPENDING SUMMARY | F34: DAILY SPENDING SUMMARY (from Master Itinerary)
A35: Category | B35: Estimated (PHP) | C35: Actual (PHP) | D35: % of Estimated Total | F35: Day | G35: Date | H35: Estimated Spend (PHP)
A36: Flights | B36: =SUMIF($B$8:$B$21,A36,$F$8:$F$21) -> 22319.42 | C36: =SUMIF($B$8:$B$21,A36,$G$8:$G$21) -> 22319.42 | D36: =IFERROR(B36/$D$26,0) -> 0.29785986 | F36: Day 1 | G36: =Dashboard!$C$9+0 -> 46461 | H36: =SUMIF('Master Itinerary'!$B:$B,G36,'Master Itinerary'!$L:$L) -> 0
A37: Hotel | B37: =SUMIF($B$8:$B$21,A37,$F$8:$F$21) -> 6948 | C37: =SUMIF($B$8:$B$21,A37,$G$8:$G$21) -> 0 | D37: =IFERROR(B37/$D$26,0) -> 0.092723303 | F37: Day 2 | G37: =Dashboard!$C$9+1 -> 46462 | H37: =SUMIF('Master Itinerary'!$B:$B,G37,'Master Itinerary'!$L:$L) -> 1370.3
A38: Travel insurance | B38: =SUMIF($B$8:$B$21,A38,$F$8:$F$21) -> 900 | C38: =SUMIF($B$8:$B$21,A38,$G$8:$G$21) -> 0 | D38: =IFERROR(B38/$D$26,0) -> 0.01201079 | F38: Day 3 | G38: =Dashboard!$C$9+2 -> 46463 | H38: =SUMIF('Master Itinerary'!$B:$B,G38,'Master Itinerary'!$L:$L) -> 3667
A39: Airport transportation | B39: =SUMIF($B$8:$B$21,A39,$F$8:$F$21) -> 1235.2 | C39: =SUMIF($B$8:$B$21,A39,$G$8:$G$21) -> 0 | D39: =IFERROR(B39/$D$26,0) -> 0.016484143 | F39: Day 4 | G39: =Dashboard!$C$9+3 -> 46464 | H39: =SUMIF('Master Itinerary'!$B:$B,G39,'Master Itinerary'!$L:$L) -> 3474
A40: MRT/local transportation | B40: =SUMIF($B$8:$B$21,A40,$F$8:$F$21) -> 1930 | C40: =SUMIF($B$8:$B$21,A40,$G$8:$G$21) -> 0 | D40: =IFERROR(B40/$D$26,0) -> 0.025756473 | F40: Day 5 | G40: =Dashboard!$C$9+4 -> 46465 | H40: =SUMIF('Master Itinerary'!$B:$B,G40,'Master Itinerary'!$L:$L) -> 7469.1
A41: Food | B41: =SUMIF($B$8:$B$21,A41,$F$8:$F$21) -> 18528 | C41: =SUMIF($B$8:$B$21,A41,$G$8:$G$21) -> 0 | D41: =IFERROR(B41/$D$26,0) -> 0.24726214 | F41: Day 6 | G41: =Dashboard!$C$9+5 -> 46466 | H41: =SUMIF('Master Itinerary'!$B:$B,G41,'Master Itinerary'!$L:$L) -> 0
A42: Attractions | B42: =SUMIF($B$8:$B$21,A42,$F$8:$F$21) -> 3667 | C42: =SUMIF($B$8:$B$21,A42,$G$8:$G$21) -> 0 | D42: =IFERROR(B42/$D$26,0) -> 0.048937299
A43: Tours | B43: =SUMIF($B$8:$B$21,A43,$F$8:$F$21) -> 4632 | C43: =SUMIF($B$8:$B$21,A43,$G$8:$G$21) -> 0 | D43: =IFERROR(B43/$D$26,0) -> 0.061815535
A44: SIM/eSIM | B44: =SUMIF($B$8:$B$21,A44,$F$8:$F$21) -> 1158 | C44: =SUMIF($B$8:$B$21,A44,$G$8:$G$21) -> 0 | D44: =IFERROR(B44/$D$26,0) -> 0.015453884
...

Sheet Bookings
A1: FLIGHTS, HOTEL & BOOKINGS
A2: All confirmed and pending reservations for the trip. Blue text = editable input cell.
A4: Booking Type | B4: Provider | C4: Date | D4: Time | E4: Location | F4: Confirmation # | G4: Cost | H4: Currency | I4: PHP Equivalent | J4: Paid? | K4: Payment Deadline | L4: Cancellation Deadline | M4: Status | N4: Link | O4: Notes
A5: Flight - Outbound | B5: Cebu Pacific (5J) | C5: =Dashboard!$C$9 -> 46461 | D5: 23:35 | E5: Manila (MNL) → Taipei Taoyuan (TPE) | F5: Kimberly: JPU86R · Kriza: SKKC5G | G5: 8000 | H5: PHP | I5: =IF(H5="TWD",G5*FXRate,G5) -> 8000 | J5: Yes | K5: =Dashboard!$C$9-45 -> 46416 | M5: Confirmed | O5: Departs Manila 11:35 PM Mar 15, arrives Taipei 2:00 AM Mar 16 (+1 day) · Confirm flight number, terminal and baggage allowance on the e-ticket · Promo fares are usually non-refundable
A6: Flight - Return | B6: Cebu Pacific (5J) | C6: =Dashboard!$C$10 -> 46466 | D6: 03:15 | E6: Taipei Taoyuan (TPE) → Manila (MNL) | F6: Kimberly: JPU86R · Kriza: SKKC5G | G6: 8500 | H6: PHP | I6: =IF(H6="TWD",G6*FXRate,G6) -> 8500 | J6: Yes | K6: =Dashboard!$C$9-45 -> 46416 | M6: Confirmed | O6: Departs Taipei 3:15 AM, arrives Manila 5:45 AM, both Mar 20 · Very early departure – leave the hotel by ~21:00–21:30 the night before · Confirm flight number and terminal on the e-ticket
A7: Hotel | B7: Agoda / Booking.com (sample) | C7: =Dashboard!$C$9+1 -> 46462 | D7: 15:00 | E7: Hotel near Zhongshan MRT, Zhongshan District, Taipei | F7: HTL-SAMPLE-001 | G7: 3600 | H7: TWD | I7: =IF(H7="TWD",G7*FXRate,G7) -> 6948 | J7: No | K7: =Dashboard!$C$9-30 -> 46431 | L7: =Dashboard!$C$9-2 -> 46459 | M7: Not Started | O7: =(Dashboard!$C$10-(Dashboard!$C$9+1))&" nights (Mar 16–20) · Twin/Double room · Breakfast included · No 2nd hotel night needed – the 3:15 AM Mar 20 flight departs from the same night's stay" -> 4 nights (Mar 16–20) · Twin/Double room · Breakfast included · No 2nd hotel night needed – the 3:15 AM Mar 20 flight departs from the same night's stay
A8: Airport Transfer - Arrival | B8: Taoyuan Airport MRT / taxi | C8: =Dashboard!$C$9+1 -> 46462 | D8: 03:00 | E8: Taoyuan Airport (TPE) → Hotel (Zhongshan) | F8: N/A | G8: 1000 | H8: TWD | I8: =IF(H8="TWD",G8*FXRate,G8) -> 1930 | J8: No | M8: Not Started | O8: 2 pax · Landing at 2:00 AM – first Airport MRT train is ~6:00 AM, so budget for a taxi (~NT$1,000–1,200) if heading straight to the hotel
A9: Airport Transfer - Departure | B9: Taoyuan Airport MRT / taxi | C9: =Dashboard!$C$10-1 -> 46465 | D9: 21:00 | E9: Hotel (Zhongshan) → Taoyuan Airport (TPE) | F9: N/A | G9: 320 | H9: TWD | I9: =IF(H9="TWD",G9*FXRate,G9) -> 617.6 | J9: No | M9: Not Started | O9: 2 pax · Depart the night of Mar 19 for the 3:15 AM Mar 20 flight · Airport MRT runs until around midnight, taxi after that
A10: Tour - Jiufen & Shifen Day Trip | B10: Klook / KKday (sample) | C10: =Dashboard!$C$9+4 -> 46465 | D10: 08:00 | E10: Hotel pickup → Shifen → Jiufen → Hotel | F10: TOUR-SAMPLE-01 | G10: 2400 | H10: TWD | I10: =IF(H10="TWD",G10*FXRate,G10) -> 4632 | J10: No | K10: =Dashboard!$C$9+1 -> 46462 | L10: =Dashboard!$C$9+2 -> 46463 | M10: Not Started | O10: 2 pax · Small-group day tour · Includes sky lantern · Runs on the last day – luggage stays at the hotel front desk after check-out
A11: Attraction Ticket - Taipei 101 Observatory | B11: Official site / Klook | C11: =Dashboard!$C$9+2 -> 46463 | D11: 09:30 | E11: Taipei 101, Xinyi District | F11: T101-SAMPLE | G11: 1200 | H11: TWD | I11: =IF(H11="TWD",G11*FXRate,G11) -> 2316 | J11: No | M11: Not Started | O11: 2 pax · 89F indoor observatory · Book online in advance for discount and to skip queue
A12: Attraction Ticket - National Palace Museum | B12: Official site (npm.gov.tw) | C12: =Dashboard!$C$9+3 -> 46464 | D12: 09:00 | E12: National Palace Museum, Shilin District | F12: NPM-SAMPLE | G12: 700 | H12: TWD | I12: =IF(H12="TWD",G12*FXRate,G12) -> 1351 | J12: No | M12: Not Started | O12: 2 pax · Regular adult ticket · Closed Mondays – confirm open days before booking
A13: SIM / eSIM | B13: Klook / Chunghwa Telecom | C13: =Dashboard!$C$9 -> 46461 | D13: N/A | E13: Collect at airport or install before departure | F13: SIM-SAMPLE | G13: 600 | H13: TWD | I13: =IF(H13="TWD",G13*FXRate,G13) -> 1158 | J13: No | M13: Not Started | O13: 2 pax · 5-day unlimited data eSIM/SIM – install before the overnight flight if using an eSIM
A14: Restaurant Reservation (optional) | B14: Din Tai Fung, Xinyi | C14: =Dashboard!$C$9+2 -> 46463 | D14: 19:00 | E14: Din Tai Fung, Taipei 101 Mall | F14: N/A | G14: 0 | H14: TWD | I14: =IF(H14="TWD",G14*FXRate,G14) -> 0 | J14: N/A | M14: Not Started | O14: Optional – book online in advance, especially for dinner slots

Sheet Packing & Pre-Trip
A1: PACKING & PRE-TRIP CHECKLIST
A2: Tick off items as you pack. Completion percentages update automatically.
A4: PACKING LIST
A5: Item | B5: Category | C5: Quantity | D5: Packed? | E5: Carry-on/Checked | F5: Priority | G5: Notes
A6: Passport | B6: Passport/documents | C6: 2 | D6: No | E6: Carry-on | F6: High | G6: Keep in a travel wallet with visas/tickets
A7: Printed hotel & flight confirmations | B7: Passport/documents | C7: 2 | D7: No | E7: Carry-on | F7: High | G7: Also saved digitally
A8: TWAC confirmation (screenshot/printout) | B8: Passport/documents | C8: 1 | D8: No | E8: Carry-on | F8: High | G8: Submit online within 3 days before arrival
A9: Cash (PHP + some TWD) | B9: Money/cards | C9: 1 | D9: No | E9: Carry-on | F9: High | G9: Small TWD amount for arrival before exchanging more
A10: Debit/credit cards | B10: Money/cards | C10: 2 | D10: No | E10: Carry-on | F10: High | G10: Notify your bank of international travel
A11: Travel wallet/pouch | B11: Money/cards | C11: 1 | D11: No | E11: Carry-on | F11: Medium | G11: Keep documents and cards together
A12: T-shirts / tops | B12: Clothing | C12: 6 | D12: No | E12: Checked | F12: Medium | G12: Layer-friendly for cool November evenings
A13: Light jacket / cardigan | B13: Clothing | C13: 1 | D13: No | E13: Checked | F13: High | G13: Evenings and Beitou/Elephant Mtn can be cool
A14: Pants/shorts | B14: Clothing | C14: 3 | D14: No | E14: Checked | F14: Medium | G14: Mix of long pants and shorts
A15: Sleepwear | B15: Clothing | C15: 2 | D15: No | E15: Checked | F15: Low
A16: Undergarments & socks | B16: Clothing | C16: 7 | D16: No | E16: Checked | F16: High
A17: Comfortable walking shoes | B17: Shoes | C17: 1 | D17: No | E17: Checked | F17: High | G17: Essential for Jiufen, Elephant Mountain, night markets
A18: Sandals/flip-flops | B18: Shoes | C18: 1 | D18: No | E18: Checked | F18: Low | G18: For hotel or hot spring use
A19: Toothbrush & toothpaste | B19: Toiletries | C19: 1 | D19: No | E19: Checked | F19: Medium
A20: Skincare/sunscreen | B20: Toiletries | C20: 1 | D20: No | E20: Checked | F20: Medium | G20: Keep liquids under 100ml in carry-on
A21: Shampoo/soap (travel size) | B21: Toiletries | C21: 1 | D21: No | E21: Checked | F21: Low | G21: Most hotels provide basics
A22: Feminine hygiene/personal care items | B22: Toiletries | C22: 1 | D22: No | E22: Checked | F22: Medium
A23: Phone + charging cable | B23: Electronics | C23: 1 | D23: No | E23: Carry-on | F23: High
A24: Power bank | B24: Electronics | C24: 1 | D24: No | E24: Checked | F24: Medium | G24: Under 20,000mAh for airline compliance – verify with airline
A25: Camera | B25: Electronics | C25: 1 | D25: No | E25: Carry-on | F25: Low | G25: Optional – phone camera may be enough
A26: Universal/Taiwan travel adapter (Type A/B) | B26: Chargers/adapters | C26: 1 | D26: No | E26: Checked | F26: High | G26: Taiwan uses Type A/B sockets, 110V – same as Philippines
A27: Extra charging cables | B27: Chargers/adapters | C27: 2 | D27: No | E27: Checked | F27: Medium
A28: Portable multi-USB charger | B28: Chargers/adapters | C28: 1 | D28: No | E28: Checked | F28: Low
A29: Personal medications | B29: Medicines/basic first aid | C29: 1 | D29: No | E29: Carry-on | F29: High | G29: Bring in original packaging with prescription if needed
A30: Basic first aid kit (band-aids, pain reliever) | B30: Medicines/basic first aid | C30: 1 | D30: No | E30: Checked | F30: Medium
A31: Motion sickness / anti-diarrheal tablets | B31: Medicines/basic first aid | C31: 1 | D31: No | E31: Checked | F31: Low
A32: Compact umbrella | B32: Umbrella/rain gear | C32: 1 | D32: No | E32: Carry-on | F32: High | G32: November can bring rain showers
A33: Light rain jacket/poncho | B33: Umbrella/rain gear | C33: 1 | D33: No | E33: Checked | F33: Medium | G33: Useful for Jiufen/Shifen day trip
A34: Day bag/backpack | B34: Travel accessories | C34: 1 | D34: No | E34: Carry-on | F34: High | G34: For daily excursions
A35: Reusable water bottle | B35: Travel accessories | C35: 1 | D35: No | E35: Checked | F35: Medium | G35: Refill stations common at MRT stations
A36: Luggage lock & tags | B36: Travel accessories | C36: 2 | D36: No | E36: Checked | F36: Low
A37: Neck pillow | B37: Carry-on essentials | C37: 1 | D37: No | E37: Carry-on | F37: Low | G37: For the flight
A38: Snacks for the flight | B38: Carry-on essentials | C38: 1 | D38: No | E38: Carry-on | F38: Low
A39: Face mask & hand sanitizer | B39: Carry-on essentials | C39: 1 | D39: No | E39: Carry-on | F39: Medium
A40: PACKING COMPLETION % | D40: =COUNTIF(D6:D39,"Yes")/COUNTA(A6:A39) -> 0
A42: PRE-TRIP TASKS
...

Sheet Food & Places
A1: FOOD & PLACES – QUICK REFERENCE
A2: A handy shortlist – not exhaustive. Prices and hours can change; verify for anything time-sensitive.
A4: MUST-TRY TAIWANESE FOOD
A5: Food/Restaurant | B5: Area | C5: Meal | D5: Estimated Cost | E5: Opening Hours | F5: Reservation? | G5: Must Try? | H5: Notes
A6: Beef noodle soup | B6: Citywide (try Yongkang St) | C6: Lunch/Dinner | D6: 180 | E6: 11:00–21:00 (varies) | F6: Not Required | G6: Yes | H6: Taipei's signature comfort dish
A7: Xiao long bao (Din Tai Fung) | B7: Xinyi / citywide branches | C7: Lunch/Dinner | D7: 400 | E7: 11:00–21:00 | F7: Recommended | G7: Yes | H7: Expect a queue at peak hours; book online where possible
A8: Gua bao (braised pork bun) | B8: Night markets / Huaxi St | C8: Snack | D8: 60 | E8: Evening, varies by stall | F8: Not Required | G8: Yes | H8: Sometimes called 'Taiwanese hamburger'
A9: Lu rou fan (braised pork rice) | B9: Citywide | C9: Lunch/Dinner | D9: 90 | E9: 11:00–20:00 (varies) | F9: Not Required | G9: Yes | H9: Simple, cheap, and everywhere
A10: Taiwanese fried chicken (Hot Star style) | B10: Shilin / Ximending night markets | C10: Snack | D10: 80 | E10: Evening, varies by stall | F10: Not Required | G10: Yes | H10: Look for the long queues – usually a good sign
A11: Scallion pancake | B11: Night markets / street stalls | C11: Snack | D11: 50 | E11: Evening, varies by stall | F11: Not Required | G11: Yes | H11: Crispy, savory, best fresh off the griddle
A12: Oyster omelet | B12: Night markets (Shilin, Raohe) | C12: Snack/Dinner | D12: 90 | E12: Evening, varies by stall | F12: Not Required | G12: Yes | H12: A Taiwanese night-market classic
A13: Bubble tea | B13: Citywide | C13: Snack | D13: 60 | E13: 10:00–22:00 (varies) | F13: Not Required | G13: Yes | H13: Taiwan is the birthplace of boba
A14: Pineapple cake | B14: Bakeries / airport / Dihua St | C14: Snack/Souvenir | D14: 250 | E14: 10:00–20:00 (varies) | F14: Not Required | G14: Yes | H14: Buy near the airport for the freshest box to bring home
A15: Night-market snack crawl | B15: Shilin / Raohe / Ningxia | C15: Dinner | D15: 400 | E15: 17:00–23:00 (varies) | F15: Not Required | G15: Yes | H15: Budget for grazing across several stalls
A17: PLACES TO VISIT
A18: Attraction | B18: Area | C18: Type | D18: Recommended Duration | E18: Opening Hours | F18: Entrance Fee | G18: Best Time | H18: Nearest MRT | I18: Priority | J18: Visited? | K18: Notes
A19: Taipei 101 Observatory | B19: Xinyi | C19: Must See | D19: 1.5–2 hrs | E19: 10:00–21:00 | F19: NT$600 | G19: Late afternoon for sunset+night view | H19: Taipei 101/World Trade Center | I19: High | J19: No | K19: Book online in advance; go near sunset for both daylight and night skyline views
A20: Ximending | B20: Wanhua | C20: Must See | D20: 2–3 hrs | E20: Shops ~11:00–22:00 | F20: Free to walk | G20: Evening | H20: Ximen | I20: High | J20: No | K20: Great for shopping, arcades, cinemas, and street food
A21: Chiang Kai-shek Memorial Hall | B21: Zhongzheng | C21: Must See | D21: 1–1.5 hrs | E21: 9:00–18:00 | F21: Free | G21: Morning (guard ceremony hourly) | H21: CKS Memorial Hall | I21: High | J21: No | K21: Hourly changing-of-the-guard ceremony is a highlight
A22: Longshan Temple | B22: Wanhua | C22: Must See | D22: 45–60 min | E22: 6:00–22:00 | F22: Free | G22: Morning, less crowded | H22: Longshan Temple | I22: High | J22: No | K22: Taipei's oldest and most important temple
A23: Dihua Street | B23: Datong | C23: Recommended | D23: 1–2 hrs | E23: 10:00–19:00 (varies) | F23: Free to walk | G23: Weekday morning | H23: Beimen | I23: Medium | J23: No | K23: Historic dried-goods and herbal medicine street
A24: Shilin Night Market | B24: Shilin | C24: Must See | D24: 1.5–2.5 hrs | E24: 16:00–24:00 (varies) | F24: Free to enter | G24: Evening | H24: Jiantan | I24: High | J24: No | K24: One of Taipei's largest and most famous night markets
A25: Raohe Street Night Market | B25: Songshan | C25: Recommended | D25: 1–1.5 hrs | E25: 17:00–24:00 (varies) | F25: Free to enter | G25: Evening | H25: Songshan | I25: Medium | J25: No | K25: Michelin Bib Gourmand street food stalls
A26: National Palace Museum | B26: Shilin | C26: Must See | D26: 3–4 hrs | E26: Tue–Sun 9:00–17:00, closed Mon | F26: NT$350 | G26: Weekday morning | H26: Shilin + shuttle bus | I26: High | J26: No | K26: Home of the Jadeite Cabbage and Meat-Shaped Stone
A27: Beitou Hot Spring / Thermal Valley | B27: Beitou | C27: Recommended | D27: 2–3 hrs | E27: Varies by spa; Thermal Valley 9:00–17:00 | F27: NT$300–800 | G27: Afternoon | H27: Xinbeitou | I27: Medium | J27: No | K27: Relaxing afternoon; some spas require reservations
A28: Elephant Mountain (Xiangshan) | B28: Xinyi | C28: Weather Dependent | D28: 1–1.5 hrs | E28: Trail always open (daylight best) | F28: Free | G28: 1 hr before sunset | H28: Xiangshan | I28: Medium | J28: No | K28: Iconic sunset hiking spot overlooking Taipei 101
A29: Huashan 1914 Creative Park | B29: Zhongzheng/Zhongshan | C29: Optional | D29: 1–2 hrs | E29: Grounds 24hrs; exhibits vary | F29: Free grounds; exhibits ticketed | G29: Afternoon | H29: Zhongxiao Xinsheng | I29: Low | J29: No | K29: Former winery turned creative/arts park
... A31: Shifen Old Street & Waterfall | B31: New Taipei City | C31: Recommended | D31: 2–3 hrs | E31: Daylight hours | F31: Free (lantern ~NT$150) | G31: Midday | H31: N/A (Pingxi Line train) | I31: Medium | J31: No | K31: Sky lantern releases and a scenic waterfall
